<?xml version="1.0"?>
<robot xmlns:xacro="http://ros.org/wiki/xacro">
    <xacro:include filename="$(find le_arm)/urdf/le_arm.transmission.xacro" />
    <xacro:include filename="$(find le_arm)/urdf/le_arm_gripper.urdf.xacro" />
    <xacro:macro name="le_arm" params="prefix parent *origin">  
        <joint name="${prefix}base_joint" type="fixed">
            <parent link="${parent}"/>
            <child link="${prefix}base_link"/>
            <xacro:insert_block name="origin"/>
        </joint>

        <link
            name="base_link">
            <inertial>
            <origin
                xyz="0.034411 3.2244E-06 0.02029"
                rpy="0 0 0" />
            <mass
                value="0.99333" />
            <inertia
                ixx="0.00080801"
                ixy="-3.0513E-07"
                ixz="0.00070004"
                iyy="0.0017712"
                iyz="6.5691E-08"
                izz="0.0012132" />
            </inertial>
            <visual>
            <origin
                xyz="0 0 0"
                rpy="0 0 0" />
            <geometry>
                <mesh
                filename="package://le_arm/meshes/arm/base_link.STL" />
            </geometry>
            <material
                name="">
                <color
                rgba="0.75294 0.75294 0.75294 1" />
            </material>
            </visual>
            <collision>
            <origin
                xyz="0 0 0"
                rpy="0 0 0" />
            <geometry>
                <mesh
                filename="package://le_arm/meshes/arm/base_link.STL" />
            </geometry>
            </collision>
        </link>

        <gazebo reference="${prefix}base_link">
            <implicitSpringDamper>1</implicitSpringDamper>
            <mu1>100000</mu1>
            <mu2>100000</mu2>
            <kp>100000000.0</kp>
            <kd>1.0</kd>
        </gazebo> 

        <link
            name="shoulder_link">
            <inertial>
            <origin
                xyz="-0.0005946 -0.00090913 0.017195"
                rpy="0 0 0" />
            <mass
                value="0.23189" />
            <inertia
                ixx="4.567E-05"
                ixy="-1.6514E-07"
                ixz="6.1923E-07"
                iyy="3.8122E-05"
                iyz="2.9921E-06"
                izz="2.4252E-05" />
            </inertial>
            <visual>
            <origin
                xyz="0 0 0"
                rpy="0 0 0" />
            <geometry>
                <mesh
                filename="package://le_arm/meshes/arm/shoulder_link.STL" />
            </geometry>
            <material
                name="">
                <color
                rgba="0.75294 0.75294 0.75294 1" />
            </material>
            </visual>
            <collision>
            <origin
                xyz="0 0 0"
                rpy="0 0 0" />
            <geometry>
                <mesh
                filename="package://le_arm/meshes/arm/shoulder_link.STL" />
            </geometry>
            </collision>
        </link>

                
        <gazebo reference="${prefix}shoulder_link">
            <implicitSpringDamper>1</implicitSpringDamper>
            <mu1>100000</mu1>
            <mu2>100000</mu2>
            <kp>100000000.0</kp>
            <kd>1.0</kd>
        </gazebo> 

        <joint
            name="shoulder_pan_joint"
            type="revolute">
            <origin
            xyz="0.0005 0 0.0535"
            rpy="0 0 3.14159" />
            <parent
            link="base_link" />
            <child
            link="shoulder_link" />
            <axis
            xyz="0 0 1" />
            <limit
            lower="-2.356"
            upper="2.356"
            effort="1000"
            velocity="2" />
        </joint>
        <link
            name="upper_arm_link">
            <inertial>
            <origin
                xyz="2.6345E-08 -0.02405 0.05197"
                rpy="0 0 0" />
            <mass
                value="0.16412" />
            <inertia
                ixx="0.00016894"
                ixy="1.0044E-10"
                ixz="2.2451E-10"
                iyy="0.00014857"
                iyz="4.9533E-09"
                izz="2.0874E-05" />
            </inertial>
            <visual>
            <origin
                xyz="0 0 0"
                rpy="0 0 0" />
            <geometry>
                <mesh
                filename="package://le_arm/meshes/arm/upper_arm_link.STL" />
            </geometry>
            <material
                name="">
                <color
                rgba="0.75294 0.75294 0.75294 1" />
            </material>
            </visual>
            <collision>
            <origin
                xyz="0 0 0"
                rpy="0 0 0" />
            <geometry>
                <mesh
                filename="package://le_arm/meshes/arm/upper_arm_link.STL" />
            </geometry>
            </collision>
        </link>

        <gazebo reference="${prefix}upper_arm_link">
            <implicitSpringDamper>1</implicitSpringDamper>
            <mu1>100000</mu1>
            <mu2>100000</mu2>
            <kp>100000000.0</kp>
            <kd>1.0</kd>
        </gazebo> 

        <joint
            name="shoulder_lift_joint" 
            type="revolute">
            <origin
            xyz="-0.0105 0.0226 0.032"
            rpy="-5.7183E-11 0 0" />
            <parent
            link="shoulder_link" />
            <child
            link="upper_arm_link" />
            <axis
            xyz="0 1 0" />
            <limit
            lower="-2.356"
            upper="2.356"
            effort="1000"
            velocity="2" />
        </joint>
        <link
            name="forearm_link">
            <inertial>
            <origin
                xyz="3.5006E-08 0.0090395 0.033861"
                rpy="0 0 0" />
            <mass
                value="0.16334" />
            <inertia
                ixx="0.00011198"
                ixy="8.5623E-11"
                ixz="2.0085E-10"
                iyy="0.00010041"
                iyz="1.8708E-06"
                izz="1.1804E-05" />
            </inertial>
            <visual>
            <origin
                xyz="0 0 0"
                rpy="0 0 0" />
            <geometry>
                <mesh
                filename="package://le_arm/meshes/arm/forearm_link.STL" />
            </geometry>
            <material
                name="">
                <color
                rgba="0.75294 0.75294 0.75294 1" />
            </material>
            </visual>
            <collision>
            <origin
                xyz="0 0 0"
                rpy="0 0 0" />
            <geometry>
                <mesh
                filename="package://le_arm/meshes/arm/forearm_link.STL" />
            </geometry>
            </collision>
        </link>

        <gazebo reference="${prefix}forearm_link">
            <implicitSpringDamper>1</implicitSpringDamper>
            <mu1>100000</mu1>
            <mu2>100000</mu2>
            <kp>100000000.0</kp>
            <kd>1.0</kd>
        </gazebo> 


        <joint
            name="elbow_joint"
            type="revolute">
            <origin
            xyz="0 -0.0335 0.104"
            rpy="-1.6E-10 0 0" />
            <parent
            link="upper_arm_link" />
            <child
            link="forearm_link" />
            <axis
            xyz="0 1 0" />
            <limit
            lower="-2.356"
            upper="2.356"
            effort="1000"
            velocity="2" />
        </joint>
        <link
            name="wrist_1_link">
            <inertial>
            <origin
                xyz="-0.010432 0.010212 0.019017"
                rpy="0 0 0" />
            <mass
                value="0.19648" />
            <inertia
                ixx="7.2115E-05"
                ixy="4.9825E-07"
                ixz="-1.1322E-06"
                iyy="7.9549E-05"
                iyz="-1.2244E-06"
                izz="2.7014E-05" />
            </inertial>
            <visual>
            <origin
                xyz="0 0 0"
                rpy="0 0 0" />
            <geometry>
                <mesh
                filename="package://le_arm/meshes/arm/wrist_1_link.STL" />
            </geometry>
            <material
                name="">
                <color
                rgba="0.75294 0.75294 0.75294 1" />
            </material>
            </visual>
            <collision>
            <origin
                xyz="0 0 0"
                rpy="0 0 0" />
            <geometry>
                <mesh
                filename="package://le_arm/meshes/arm/wrist_1_link.STL" />
            </geometry>
            </collision>
        </link>

         <gazebo reference="${prefix}wrist_1_link">
            <implicitSpringDamper>1</implicitSpringDamper>
            <mu1>100000</mu1>
            <mu2>100000</mu2>
            <kp>100000000.0</kp>
            <kd>1.0</kd>
        </gazebo> 

        <joint
            name="wrist_1_joint"
            type="revolute">
            <origin
            xyz="-0.0007415 0.02 0.098419"
            rpy="0 0 3.14159" />
            <parent
            link="forearm_link" />
            <child
            link="wrist_1_link" />
            <axis
            xyz="0 1 0" />
            <limit
            lower="-2.356"
            upper="2.356"
            effort="1000"
            velocity="2" />
        </joint>  


        <xacro:le_arm_gripper prefix="" parent="wrist_1_link" > <!--调用le_arm_gripper.urdf.xacro定义的宏-->
            <origin xyz="0 0.009 0.059" rpy="0 0 3.14159"/>
        </xacro:le_arm_gripper>


        <xacro:le_arm_transmission prefix="${prefix}"/>

    </xacro:macro>    
</robot>