<?xml version="1.0" ?>
<!-- =================================================================================== -->
<!-- |    This document was autogenerated by xacro from le_arm.xacro                   | -->
<!-- |    EDITING THIS FILE BY HAND IS NOT RECOMMENDED                                 | -->
<!-- =================================================================================== -->
<robot name="le_arm" xmlns:xacro="http://ros.org/wiki/xacro">
  <gazebo>
    <plugin filename="libgazebo_ros_control.so" name="gazebo_ros_control">
      <robotNamespace>/</robotNamespace>
    </plugin>
  </gazebo>
  <link name="world"/>
  <joint name="world_fixed" type="fixed">
    <origin rpy="0 0 0" xyz="0 0 0"/>
    <parent link="world"/>
    <child link="root_link"/>
  </joint>
  <link name="root_link">
    <visual>
      <origin rpy="0 0 0" xyz="0 0 0.005"/>
      <geometry>
        <box size="0.46 0.25 0.01"/>
      </geometry>
      <material name="">
        <color rgba="0 0 0 1"/>
      </material>
    </visual>
    <inertial>
      <mass value="1e2"/>
      <origin xyz="0.0 0.0 0.0"/>
      <inertia ixx="0.000001" ixy="0.000000" ixz="0.000000" iyx="0.000000" iyy="0.000001" iyz="0.000000" izx="0.000000" izy="0.000000" izz="0.000001"/>
    </inertial>
  </link>
  <joint name="base_joint" type="fixed">
    <parent link="root_link"/>
    <child link="base_link"/>
    <origin rpy="0 0 0" xyz="0.0 0.0 0.02"/>
  </joint>
  <link name="base_link">
    <inertial>
      <origin rpy="0 0 0" xyz="0.034411 3.2244E-06 0.02029"/>
      <mass value="0.99333"/>
      <inertia ixx="0.00080801" ixy="-3.0513E-07" ixz="0.00070004" iyy="0.0017712" iyz="6.5691E-08" izz="0.0012132"/>
    </inertial>
    <visual>
      <origin rpy="0 0 0" xyz="0 0 0"/>
      <geometry>
        <mesh filename="package://le_arm/meshes/arm/base_link.STL"/>
      </geometry>
      <material name="">
        <color rgba="0.75294 0.75294 0.75294 1"/>
      </material>
    </visual>
    <collision>
      <origin rpy="0 0 0" xyz="0 0 0"/>
      <geometry>
        <mesh filename="package://le_arm/meshes/arm/base_link.STL"/>
      </geometry>
    </collision>
  </link>
  <gazebo reference="base_link">
    <implicitSpringDamper>1</implicitSpringDamper>
    <mu1>100000</mu1>
    <mu2>100000</mu2>
    <kp>100000000.0</kp>
    <kd>1.0</kd>
  </gazebo>
  <link name="shoulder_link">
    <inertial>
      <origin rpy="0 0 0" xyz="-0.0005946 -0.00090913 0.017195"/>
      <mass value="0.23189"/>
      <inertia ixx="4.567E-05" ixy="-1.6514E-07" ixz="6.1923E-07" iyy="3.8122E-05" iyz="2.9921E-06" izz="2.4252E-05"/>
    </inertial>
    <visual>
      <origin rpy="0 0 0" xyz="0 0 0"/>
      <geometry>
        <mesh filename="package://le_arm/meshes/arm/shoulder_link.STL"/>
      </geometry>
      <material name="">
        <color rgba="0.75294 0.75294 0.75294 1"/>
      </material>
    </visual>
    <collision>
      <origin rpy="0 0 0" xyz="0 0 0"/>
      <geometry>
        <mesh filename="package://le_arm/meshes/arm/shoulder_link.STL"/>
      </geometry>
    </collision>
  </link>
  <gazebo reference="shoulder_link">
    <implicitSpringDamper>1</implicitSpringDamper>
    <mu1>100000</mu1>
    <mu2>100000</mu2>
    <kp>100000000.0</kp>
    <kd>1.0</kd>
  </gazebo>
  <joint name="shoulder_pan_joint" type="revolute">
    <origin rpy="0 0 3.14159" xyz="0.0005 0 0.0535"/>
    <parent link="base_link"/>
    <child link="shoulder_link"/>
    <axis xyz="0 0 1"/>
    <limit effort="1000" lower="-2.356" upper="2.356" velocity="2"/>
  </joint>
  <link name="upper_arm_link">
    <inertial>
      <origin rpy="0 0 0" xyz="2.6345E-08 -0.02405 0.05197"/>
      <mass value="0.16412"/>
      <inertia ixx="0.00016894" ixy="1.0044E-10" ixz="2.2451E-10" iyy="0.00014857" iyz="4.9533E-09" izz="2.0874E-05"/>
    </inertial>
    <visual>
      <origin rpy="0 0 0" xyz="0 0 0"/>
      <geometry>
        <mesh filename="package://le_arm/meshes/arm/upper_arm_link.STL"/>
      </geometry>
      <material name="">
        <color rgba="0.75294 0.75294 0.75294 1"/>
      </material>
    </visual>
    <collision>
      <origin rpy="0 0 0" xyz="0 0 0"/>
      <geometry>
        <mesh filename="package://le_arm/meshes/arm/upper_arm_link.STL"/>
      </geometry>
    </collision>
  </link>
  <gazebo reference="upper_arm_link">
    <implicitSpringDamper>1</implicitSpringDamper>
    <mu1>100000</mu1>
    <mu2>100000</mu2>
    <kp>100000000.0</kp>
    <kd>1.0</kd>
  </gazebo>
  <joint name="shoulder_lift_joint" type="revolute">
    <origin rpy="-5.7183E-11 0 0" xyz="-0.0105 0.0226 0.032"/>
    <parent link="shoulder_link"/>
    <child link="upper_arm_link"/>
    <axis xyz="0 1 0"/>
    <limit effort="1000" lower="-2.356" upper="2.356" velocity="2"/>
  </joint>
  <link name="forearm_link">
    <inertial>
      <origin rpy="0 0 0" xyz="3.5006E-08 0.0090395 0.033861"/>
      <mass value="0.16334"/>
      <inertia ixx="0.00011198" ixy="8.5623E-11" ixz="2.0085E-10" iyy="0.00010041" iyz="1.8708E-06" izz="1.1804E-05"/>
    </inertial>
    <visual>
      <origin rpy="0 0 0" xyz="0 0 0"/>
      <geometry>
        <mesh filename="package://le_arm/meshes/arm/forearm_link.STL"/>
      </geometry>
      <material name="">
        <color rgba="0.75294 0.75294 0.75294 1"/>
      </material>
    </visual>
    <collision>
      <origin rpy="0 0 0" xyz="0 0 0"/>
      <geometry>
        <mesh filename="package://le_arm/meshes/arm/forearm_link.STL"/>
      </geometry>
    </collision>
  </link>
  <gazebo reference="forearm_link">
    <implicitSpringDamper>1</implicitSpringDamper>
    <mu1>100000</mu1>
    <mu2>100000</mu2>
    <kp>100000000.0</kp>
    <kd>1.0</kd>
  </gazebo>
  <joint name="elbow_joint" type="revolute">
    <origin rpy="-1.6E-10 0 0" xyz="0 -0.0335 0.104"/>
    <parent link="upper_arm_link"/>
    <child link="forearm_link"/>
    <axis xyz="0 1 0"/>
    <limit effort="1000" lower="-2.356" upper="2.356" velocity="2"/>
  </joint>
  <link name="wrist_1_link">
    <inertial>
      <origin rpy="0 0 0" xyz="-0.010432 0.010212 0.019017"/>
      <mass value="0.19648"/>
      <inertia ixx="7.2115E-05" ixy="4.9825E-07" ixz="-1.1322E-06" iyy="7.9549E-05" iyz="-1.2244E-06" izz="2.7014E-05"/>
    </inertial>
    <visual>
      <origin rpy="0 0 0" xyz="0 0 0"/>
      <geometry>
        <mesh filename="package://le_arm/meshes/arm/wrist_1_link.STL"/>
      </geometry>
      <material name="">
        <color rgba="0.75294 0.75294 0.75294 1"/>
      </material>
    </visual>
    <collision>
      <origin rpy="0 0 0" xyz="0 0 0"/>
      <geometry>
        <mesh filename="package://le_arm/meshes/arm/wrist_1_link.STL"/>
      </geometry>
    </collision>
  </link>
  <gazebo reference="wrist_1_link">
    <implicitSpringDamper>1</implicitSpringDamper>
    <mu1>100000</mu1>
    <mu2>100000</mu2>
    <kp>100000000.0</kp>
    <kd>1.0</kd>
  </gazebo>
  <joint name="wrist_1_joint" type="revolute">
    <origin rpy="0 0 3.14159" xyz="-0.0007415 0.02 0.098419"/>
    <parent link="forearm_link"/>
    <child link="wrist_1_link"/>
    <axis xyz="0 1 0"/>
    <limit effort="1000" lower="-2.356" upper="2.356" velocity="2"/>
  </joint>
  <joint name="wrist_2_joint" type="revolute">
    <origin rpy="0 0 3.14159" xyz="0 0.009 0.059"/>
    <parent link="wrist_1_link"/>
    <child link="gripper_base_link"/>
    <axis xyz="0 0 1"/>
    <limit effort="1000" lower="-2.356" upper="2.356" velocity="2"/>
  </joint>
  <link name="gripper_base_link">
    <inertial>
      <origin rpy="0 0 0" xyz="-0.016093 0.0024206 0.03061"/>
      <mass value="0.028086"/>
      <inertia ixx="3.1219E-06" ixy="-2.5375E-07" ixz="8.5389E-07" iyy="6.5006E-06" iyz="-1.1996E-07" izz="7.1641E-06"/>
    </inertial>
    <visual>
      <origin rpy="0 0 0" xyz="0 0 0"/>
      <geometry>
        <mesh filename="package://le_arm/meshes/gripper/base_link.STL"/>
      </geometry>
      <material name="">
        <color rgba="0.75294 0.75294 0.75294 1"/>
      </material>
    </visual>
    <collision>
      <origin rpy="0 0 0" xyz="0 0 0"/>
      <geometry>
        <mesh filename="package://le_arm/meshes/gripper/base_link.STL"/>
      </geometry>
    </collision>
  </link>
  <gazebo reference="gripper_base_link">
    <implicitSpringDamper>1</implicitSpringDamper>
    <mu1>100000</mu1>
    <mu2>100000</mu2>
    <kp>100000000.0</kp>
    <kd>1.0</kd>
  </gazebo>
  <link name="left_knuckle_link">
    <inertial>
      <origin rpy="0 0 0" xyz="0.0004174 0.0081181 0.00092142"/>
      <mass value="0.0024316"/>
      <inertia ixx="1.2495E-07" ixy="2.3126E-09" ixz="-5.8721E-10" iyy="9.2991E-09" iyz="2.9378E-08" izz="1.1574E-07"/>
    </inertial>
    <visual>
      <origin rpy="0 0 0" xyz="0 0 0"/>
      <geometry>
        <mesh filename="package://le_arm/meshes/gripper/left_knuckle_link.STL"/>
      </geometry>
      <material name="">
        <color rgba="0.75294 0.75294 0.75294 1"/>
      </material>
    </visual>
    <collision>
      <origin rpy="0 0 0" xyz="0 0 0"/>
      <geometry>
        <mesh filename="package://le_arm/meshes/gripper/left_knuckle_link.STL"/>
      </geometry>
    </collision>
  </link>
  <gazebo reference="left_knuckle_link">
    <implicitSpringDamper>1</implicitSpringDamper>
    <mu1>100000</mu1>
    <mu2>100000</mu2>
    <kp>100000000.0</kp>
    <kd>1.0</kd>
  </gazebo>
  <joint name="left_knuckle_joint" type="revolute">
    <origin rpy="1.5708 -0.59692 1.5708" xyz="0.0045 -0.014 0.0325"/>
    <parent link="gripper_base_link"/>
    <child link="left_knuckle_link"/>
    <axis xyz="0 0 1"/>
    <limit effort="1000" lower="-0.6" upper="0.6" velocity="2.0"/>
  </joint>
  <link name="right_knuckle_link">
    <inertial>
      <origin rpy="0 0 0" xyz="0.00045059 0.0080041 0.0020288"/>
      <mass value="0.0024778"/>
      <inertia ixx="1.411E-07" ixy="1.9567E-09" ixz="5.9037E-10" iyy="9.5283E-09" iyz="-3.0312E-08" izz="1.3178E-07"/>
    </inertial>
    <visual>
      <origin rpy="0 0 0" xyz="0 0 0"/>
      <geometry>
        <mesh filename="package://le_arm/meshes/gripper/right_knuckle_link.STL"/>
      </geometry>
      <material name="">
        <color rgba="0.75294 0.75294 0.75294 1"/>
      </material>
    </visual>
    <collision>
      <origin rpy="0 0 0" xyz="0 0 0"/>
      <geometry>
        <mesh filename="package://le_arm/meshes/gripper/right_knuckle_link.STL"/>
      </geometry>
    </collision>
  </link>
  <gazebo reference="right_knuckle_link">
    <implicitSpringDamper>1</implicitSpringDamper>
    <mu1>100000</mu1>
    <mu2>100000</mu2>
    <kp>100000000.0</kp>
    <kd>1.0</kd>
  </gazebo>
  <joint name="right_knuckle_joint" type="revolute">
    <origin rpy="1.5708 -0.69513 -1.5708" xyz="0.0075 0.014 0.0325"/>
    <parent link="gripper_base_link"/>
    <child link="right_knuckle_link"/>
    <axis xyz="0 0 -1"/>
    <limit effort="1000" lower="-1.57" upper="1.57" velocity="2.0"/>
    <mimic joint="left_knuckle_joint" multiplier="-1"/>
  </joint>
  <link name="left_inner_knuckle_link">
    <inertial>
      <origin rpy="0 0 0" xyz="-0.013801 1.3512E-10 -0.0091952"/>
      <mass value="0.001319"/>
      <inertia ixx="2.6043E-08" ixy="1.1504E-16" ixz="-2.1172E-09" iyy="1.3937E-07" iyz="1.3652E-15" izz="1.1332E-07"/>
    </inertial>
    <visual>
      <origin rpy="0 0 0" xyz="0 0 0"/>
      <geometry>
        <mesh filename="package://le_arm/meshes/gripper/left_inner_knuckle_link.STL"/>
      </geometry>
      <material name="">
        <color rgba="0.75294 0.75294 0.75294 1"/>
      </material>
    </visual>
    <collision>
      <origin rpy="0 0 0" xyz="0 0 0"/>
      <geometry>
        <mesh filename="package://le_arm/meshes/gripper/left_inner_knuckle_link.STL"/>
      </geometry>
    </collision>
  </link>
  <gazebo reference="left_inner_knuckle_link">
    <implicitSpringDamper>1</implicitSpringDamper>
    <mu1>100000</mu1>
    <mu2>100000</mu2>
    <kp>100000000.0</kp>
    <kd>1.0</kd>
  </gazebo>
  <joint name="left_inner_knuckle_joint" type="revolute">
    <origin rpy="1.5708 0.97387 1.5708" xyz="0.0099 -0.005 0.051474"/>
    <parent link="gripper_base_link"/>
    <child link="left_inner_knuckle_link"/>
    <axis xyz="0 0 1"/>
    <limit effort="1000" lower="-1.57" upper="1.57" velocity="2.0"/>
    <mimic joint="left_knuckle_joint" multiplier="1"/>
  </joint>
  <link name="left_finger_link">
    <inertial>
      <origin rpy="0 0 0" xyz="-0.0038459 0.0027734 -5.6082E-05"/>
      <mass value="0.0029301"/>
      <inertia ixx="1.0044E-07" ixy="2.7289E-08" ixz="-1.1114E-09" iyy="1.5056E-08" iyz="3.8024E-09" izz="1.0134E-07"/>
    </inertial>
    <visual>
      <origin rpy="0 0 0" xyz="0 0 0"/>
      <geometry>
        <mesh filename="package://le_arm/meshes/gripper/left_finger_link.STL"/>
      </geometry>
      <material name="">
        <color rgba="0.75294 0.75294 0.75294 1"/>
      </material>
    </visual>
    <collision>
      <origin rpy="0 0 0" xyz="0 0 0"/>
      <geometry>
        <mesh filename="package://le_arm/meshes/gripper/left_finger_link.STL"/>
      </geometry>
    </collision>
  </link>
  <gazebo reference="left_finger_link">
    <implicitSpringDamper>1</implicitSpringDamper>
    <mu1>100000</mu1>
    <mu2>100000</mu2>
    <kp>100000000.0</kp>
    <kd>1.0</kd>
  </gazebo>
  <joint name="left_finger_joint" type="revolute">
    <origin rpy="9.0533E-10 -1.7902E-09 0.53096" xyz="-0.029 0 -0.0084"/>
    <parent link="left_inner_knuckle_link"/>
    <child link="left_finger_link"/>
    <axis xyz="0 0 1"/>
    <limit effort="1000" lower="-1.57" upper="1.57" velocity="2.0"/>
    <mimic joint="left_knuckle_joint" multiplier="-1"/>
  </joint>
  <link name="right_inner_knuckle_link">
    <inertial>
      <origin rpy="0 0 0" xyz="-0.013801 4.8285E-11 0.0069248"/>
      <mass value="0.001319"/>
      <inertia ixx="2.6043E-08" ixy="-1.1384E-15" ixz="-2.1172E-09" iyy="1.3937E-07" iyz="5.1669E-16" izz="1.1332E-07"/>
    </inertial>
    <visual>
      <origin rpy="0 0 0" xyz="0 0 0"/>
      <geometry>
        <mesh filename="package://le_arm/meshes/gripper/right_inner_knuckle_link.STL"/>
      </geometry>
      <material name="">
        <color rgba="0.75294 0.75294 0.75294 1"/>
      </material>
    </visual>
    <collision>
      <origin rpy="0 0 0" xyz="0 0 0"/>
      <geometry>
        <mesh filename="package://le_arm/meshes/gripper/right_inner_knuckle_link.STL"/>
      </geometry>
    </collision>
  </link>
  <gazebo reference="right_inner_knuckle_link">
    <implicitSpringDamper>1</implicitSpringDamper>
    <mu1>100000</mu1>
    <mu2>100000</mu2>
    <kp>100000000.0</kp>
    <kd>1.0</kd>
  </gazebo>
  <joint name="right_inner_knuckle_joint" type="revolute">
    <origin rpy="-1.5708 0.87566 -1.5708" xyz="-0.00622 0.005 0.051474"/>
    <parent link="gripper_base_link"/>
    <child link="right_inner_knuckle_link"/>
    <axis xyz="0 0 1"/>
    <limit effort="1000" lower="-1.57" upper="1.57" velocity="2.0"/>
    <mimic joint="left_knuckle_joint" multiplier="-1"/>
  </joint>
  <link name="right_finger_link">
    <inertial>
      <origin rpy="0 0 0" xyz="-0.0038459 0.0027734 0.0030561"/>
      <mass value="0.0029301"/>
      <inertia ixx="1.0044E-07" ixy="2.7289E-08" ixz="1.1114E-09" iyy="1.5056E-08" iyz="-3.8024E-09" izz="1.0134E-07"/>
    </inertial>
    <visual>
      <origin rpy="0 0 0" xyz="0 0 0"/>
      <geometry>
        <mesh filename="package://le_arm/meshes/gripper/right_finger_link.STL"/>
      </geometry>
      <material name="">
        <color rgba="0.75294 0.75294 0.75294 1"/>
      </material>
    </visual>
    <collision>
      <origin rpy="0 0 0" xyz="0 0 0"/>
      <geometry>
        <mesh filename="package://le_arm/meshes/gripper/right_finger_link.STL"/>
      </geometry>
    </collision>
  </link>
  <gazebo reference="right_finger_link">
    <implicitSpringDamper>1</implicitSpringDamper>
    <mu1>100000</mu1>
    <mu2>100000</mu2>
    <kp>100000000.0</kp>
    <kd>1.0</kd>
  </gazebo>
  <joint name="right_finger_joint" type="revolute">
    <origin rpy="-3.1416 1.7902E-09 -0.43275" xyz="-0.029 0 0.01072"/>
    <parent link="right_inner_knuckle_link"/>
    <child link="right_finger_link"/>
    <axis xyz="0 0 -1"/>
    <limit effort="1000" lower="-1.57" upper="1.57" velocity="2.0"/>
    <mimic joint="left_knuckle_joint" multiplier="1"/>
  </joint>
  <!-- Grasping frame -->
  <link name="grasping_frame"/>
  <joint name="grasping_frame_joint" type="fixed">
    <parent link="gripper_base_link"/>
    <child link="grasping_frame"/>
    <origin rpy="0 -1.57 3.14159" xyz="0.0 0 0.11"/>
  </joint>
  <transmission name="wrist_2_transmission">
    <type>transmission_interface/SimpleTransmission</type>
    <joint name="wrist_2_joint">
      <hardwareInterface>hardware_interface/PositionJointInterface</hardwareInterface>
    </joint>
    <actuator name="wrist_2_motor">
      <mechanicalReduction>1</mechanicalReduction>
      <hardwareInterface>hardware_interface/PositionJointInterface</hardwareInterface>
    </actuator>
  </transmission>
  <transmission name="left_knuckle_joint_transmission">
    <type>transmission_interface/SimpleTransmission</type>
    <joint name="left_knuckle_joint">
      <hardwareInterface>hardware_interface/PositionJointInterface</hardwareInterface>
    </joint>
    <actuator name="left_knuckle_motor">
      <mechanicalReduction>1</mechanicalReduction>
      <hardwareInterface>hardware_interface/PositionJointInterface</hardwareInterface>
    </actuator>
  </transmission>
  <gazebo>
    <plugin filename="libroboticsgroup_gazebo_mimic_joint_plugin.so" name="MimicJointPlugin_right_finger">
      <joint>left_knuckle_joint</joint>
      <mimicJoint>right_finger_joint</mimicJoint>
    </plugin>
    <plugin filename="libroboticsgroup_gazebo_mimic_joint_plugin.so" name="MimicJointPlugin_right_inner_knuckle">
      <joint>left_knuckle_joint</joint>
      <mimicJoint>right_inner_knuckle_joint</mimicJoint>
      <multiplier>-1</multiplier>
      <offset>0.0</offset>
    </plugin>
    <plugin filename="libroboticsgroup_gazebo_mimic_joint_plugin.so" name="MimicJointPlugin_left_finger">
      <joint>left_knuckle_joint</joint>
      <mimicJoint>left_finger_joint</mimicJoint>
      <multiplier>-1</multiplier>
      <offset>0.0</offset>
    </plugin>
    <plugin filename="libroboticsgroup_gazebo_mimic_joint_plugin.so" name="MimicJointPlugin_left_inner_knuckle">
      <joint>left_knuckle_joint</joint>
      <mimicJoint>left_inner_knuckle_joint</mimicJoint>
    </plugin>
    <plugin filename="libroboticsgroup_gazebo_mimic_joint_plugin.so" name="Mimic_right_knuckle">
      <joint>left_knuckle_joint</joint>
      <mimicJoint>right_knuckle_joint</mimicJoint>
      <multiplier>-1</multiplier>
      <offset>0.0</offset>
    </plugin>
  </gazebo>
  <transmission name="shoulder_pan_trans">
    <type>transmission_interface/SimpleTransmission</type>
    <joint name="shoulder_pan_joint">
      <hardwareInterface>hardware_interface/PositionJointInterface</hardwareInterface>
    </joint>
    <actuator name="shoulder_pan_motor">
      <mechanicalReduction>1</mechanicalReduction>
      <hardwareInterface>hardware_interface/PositionJointInterface</hardwareInterface>
    </actuator>
  </transmission>
  <transmission name="shoulder_lift_trans">
    <type>transmission_interface/SimpleTransmission</type>
    <joint name="shoulder_lift_joint">
      <hardwareInterface>hardware_interface/PositionJointInterface</hardwareInterface>
    </joint>
    <actuator name="shoulder_lift_motor">
      <mechanicalReduction>1</mechanicalReduction>
      <hardwareInterface>hardware_interface/PositionJointInterface</hardwareInterface>
    </actuator>
  </transmission>
  <transmission name="elbow_trans">
    <type>transmission_interface/SimpleTransmission</type>
    <joint name="elbow_joint">
      <hardwareInterface>hardware_interface/PositionJointInterface</hardwareInterface>
    </joint>
    <actuator name="elbow_motor">
      <mechanicalReduction>1</mechanicalReduction>
      <hardwareInterface>hardware_interface/PositionJointInterface</hardwareInterface>
    </actuator>
  </transmission>
  <transmission name="wrist_1_trans">
    <type>transmission_interface/SimpleTransmission</type>
    <joint name="wrist_1_joint">
      <hardwareInterface>hardware_interface/PositionJointInterface</hardwareInterface>
    </joint>
    <actuator name="wrist_1_motor">
      <mechanicalReduction>1</mechanicalReduction>
      <hardwareInterface>hardware_interface/PositionJointInterface</hardwareInterface>
    </actuator>
  </transmission>
  <!--

    <link name="root_link">
        <visual>
            <origin xyz="0 0 0.5" rpy="0 0 0"/>
            <geometry>
                <box size="0.5 0.15 1.0"/>
            </geometry>
        </visual>
        <collision>
            <origin xyz="0 0 0.5" rpy="0 0 0"/>
            <geometry>
                <box size="0.5 0.15 1.0"/>
            </geometry>
        </collision>
        <inertial>
            <mass value="1e2" />
            <origin xyz="0.0 0.0 0.0" />
            <inertia ixx = "0.000001" ixy = "0.000000" ixz = "0.000000"
                     iyx = "0.000000" iyy = "0.000001" iyz = "0.000000"
                     izx = "0.000000" izy = "0.000000" izz = "0.000001" />
        </inertial>
    </link>


    <xacro:le_arm prefix="" parent="root_link" >
        <origin xyz="0.05 0 1.01" rpy="0 0 0"/>
    </xacro:le_arm>   -->
</robot>
